<?xml version="1.0"?>
<robot xmlns:xacro="http://www.ros.org/wiki/xacro" name="ffw_sg2_follower">
  <xacro:property name="meshes_file_direction" value="package://ffw_description/meshes/$(arg model)" />
  <xacro:arg name="use_sim" default="false" />
  <xacro:arg name="use_fake_hardware" default="false" />
  <xacro:arg name="fake_sensor_commands" default="false" />
  <xacro:arg name="prefix" default="" />
  <xacro:arg name="model" default="ffw_sg2_rev1_follower" />

  <xacro:include filename="$(find ffw_description)/urdf/common/follower/ffw_follower_body.xacro" />

  <xacro:include filename="$(find ffw_description)/urdf/common/rh_p12_rn_a/rh_p12_rn_a.urdf.xacro" />

  <xacro:include filename="$(find ffw_description)/ros2_control/$(arg model)/ffw_sg2_follower.ros2_control.xacro" />
  <xacro:include filename="$(find ffw_description)/ros2_control/$(arg model)/ffw_sg2_base.ros2_control.xacro" />

  <xacro:include filename="$(find ffw_description)/gazebo/$(arg model)/ffw_sg2_follower.gazebo.xacro" />

  <link name="world"/>

  <joint name="$(arg prefix)world_fixed" type="fixed">
    <parent link="world"/>
    <child link="$(arg prefix)base_link"/>
    <origin xyz="0.0 0.0 0.0" rpy="0 0 0"/>
  </joint>

  <link name="$(arg prefix)base_link">
    <visual>
      <origin xyz="0 0 0" rpy="0 0 0" />
      <geometry>
        <mesh filename="${meshes_file_direction}/base_mobile_assy.stl" scale="0.001 0.001 0.001" />
      </geometry>
      <material name="silver">
        <color rgba="0.75 0.75 0.75 1"/>
      </material>
    </visual>
    <collision>
      <origin xyz="0 0 0" rpy="0 0 0" />
      <geometry>
        <mesh filename="${meshes_file_direction}/base_mobile_assy.stl" scale="0.001 0.001 0.001" />
      </geometry>
    </collision>
    <inertial>
      <origin xyz="-8.880608700e-03 -4.758427800e-03 3.886366400e-01" />
      <mass value="5.435831600e+01" />
      <inertia ixx="1.188633900e+06" ixy="6.334393100e+02" ixz="-1.454811600e+05"
      iyy="1.090949100e+06" iyz="-5.126785200e+03"
      izz="4.492808000e+05" />
    </inertial>
  </link>

  <link name="$(arg prefix)lift_link">
    <visual>
      <origin xyz="0 0 0" rpy="0 0 0" />
      <geometry>
        <mesh filename="${meshes_file_direction}/lift_link.stl" scale="0.001 0.001 0.001" />
      </geometry>
      <material name="silver">
        <color rgba="0.75 0.75 0.75 1"/>
      </material>
    </visual>
    <collision>
      <origin xyz="0 0 0" rpy="0 0 0" />
      <geometry>
        <mesh filename="${meshes_file_direction}/lift_link.stl" scale="0.001 0.001 0.001" />
      </geometry>
    </collision>
  </link>
  <joint name="$(arg prefix)lift_fixed_joint" type="fixed">
    <parent link="$(arg prefix)base_link"/>
    <child link="$(arg prefix)lift_link"/>
    <origin xyz="0.0 0.0 0.0" rpy="0 0 0"/>
  </joint>

  <xacro:ffw_follower_body parent="$(arg prefix)base_link" prefix="$(arg prefix)">
    <origin xyz="-0.0199 0 1.4316" rpy="0 0 0" />
  </xacro:ffw_follower_body>

  <xacro:rh_p12_rn_a parent="$(arg prefix)arm_l_link7" prefix="$(arg prefix)gripper_l_">
    <origin xyz="0 0 -0.078" rpy="0 3.14159265359 0"/>
  </xacro:rh_p12_rn_a>

  <xacro:rh_p12_rn_a parent="$(arg prefix)arm_r_link7" prefix="$(arg prefix)gripper_r_">
    <origin xyz="0 0 -0.078" rpy="0 3.14159265359 0"/>
  </xacro:rh_p12_rn_a>

  <link name="$(arg prefix)left_wheel_steer_link">
    <visual>
      <origin xyz="0 0 0" rpy="0 0 0" />
      <geometry>
        <mesh filename="${meshes_file_direction}/left_wheel_steer_link.stl" scale="0.001 0.001 0.001" />
      </geometry>
      <material name="silver">
        <color rgba="0.75 0.75 0.75 1"/>
      </material>
    </visual>
    <collision>
      <origin xyz="0 0 0" rpy="0 0 0" />
      <geometry>
        <mesh filename="${meshes_file_direction}/left_wheel_steer_link.stl" scale="0.001 0.001 0.001" />
      </geometry>
    </collision>
  </link>
  <joint name="$(arg prefix)left_wheel_steer" type="revolute">
      <parent link="$(arg prefix)base_link"/>
      <child link="$(arg prefix)left_wheel_steer_link"/>
      <origin xyz="0.1371 0.2554 0.27555" rpy="0 0 0"/>
      <axis xyz="0 0 1" />
      <limit velocity="4.8" effort="1" lower="${-pi*6.0}" upper="${pi*6.0}" />
  </joint>
  <joint name="$(arg prefix)left_wheel_drive" type="revolute">
      <parent link="$(arg prefix)left_wheel_steer_link"/>
      <child link="$(arg prefix)left_wheel_drive_link"/>
      <origin xyz="0 0 -0.18905" rpy="0 0 0"/>
      <axis xyz="0 1 0" />
      <limit velocity="4.8" effort="1" lower="${-pi*6.0}" upper="${pi*6.0}" />
  </joint>
  <link name="$(arg prefix)left_wheel_drive_link">
    <visual>
      <origin xyz="0 0 0" rpy="0 0 0" />
      <geometry>
        <mesh filename="${meshes_file_direction}/left_wheel_drive_link.stl" scale="0.001 0.001 0.001" />
      </geometry>
      <material name="silver">
        <color rgba="0.75 0.75 0.75 1"/>
      </material>
    </visual>
    <collision>
      <origin xyz="0 0 0" rpy="0 0 0" />
      <geometry>
        <mesh filename="${meshes_file_direction}/left_wheel_drive_link.stl" scale="0.001 0.001 0.001" />
      </geometry>
    </collision>
  </link>

  <joint name="$(arg prefix)right_wheel_steer" type="revolute">
      <parent link="$(arg prefix)base_link"/>
      <child link="$(arg prefix)right_wheel_steer_link"/>
      <origin xyz="0.1371 -0.2554 0.27555" rpy="0 0 0"/>
      <axis xyz="0 0 1" />
      <limit velocity="4.8" effort="1" lower="${-pi*6.0}" upper="${pi*6.0}" />
  </joint>
  <link name="$(arg prefix)right_wheel_steer_link">
    <visual>
      <origin xyz="0 0 0" rpy="0 0 0" />
      <geometry>
        <mesh filename="${meshes_file_direction}/right_wheel_steer_link.stl" scale="0.001 0.001 0.001" />
      </geometry>
      <material name="silver">
        <color rgba="0.75 0.75 0.75 1"/>
      </material>
    </visual>
    <collision>
      <origin xyz="0 0 0" rpy="0 0 0" />
      <geometry>
        <mesh filename="${meshes_file_direction}/right_wheel_steer_link.stl" scale="0.001 0.001 0.001" />
      </geometry>
    </collision>
  </link>
  <joint name="$(arg prefix)right_wheel_drive" type="revolute">
      <parent link="$(arg prefix)right_wheel_steer_link"/>
      <child link="$(arg prefix)right_wheel_drive_link"/>
      <origin xyz="0 0 -0.18905" rpy="0 0 0"/>
      <axis xyz="0 1 0" />
      <limit velocity="4.8" effort="1" lower="${-pi*6.0}" upper="${pi*6.0}" />
  </joint>
  <link name="$(arg prefix)right_wheel_drive_link">
    <visual>
      <origin xyz="0 0 0" rpy="0 0 0" />
      <geometry>
        <mesh filename="${meshes_file_direction}/right_wheel_drive_link.stl" scale="0.001 0.001 0.001" />
      </geometry>
      <material name="silver">
        <color rgba="0.75 0.75 0.75 1"/>
      </material>
    </visual>
    <collision>
      <origin xyz="0 0 0" rpy="0 0 0" />
      <geometry>
        <mesh filename="${meshes_file_direction}/right_wheel_drive_link.stl" scale="0.001 0.001 0.001" />
      </geometry>
    </collision>
  </link>

  <joint name="$(arg prefix)rear_wheel_steer" type="revolute">
      <parent link="$(arg prefix)base_link"/>
      <child link="$(arg prefix)rear_wheel_steer_link"/>
      <origin xyz="-0.2899 0 0.27555" rpy="0 0 0"/>
      <axis xyz="0 0 1" />
      <limit velocity="4.8" effort="1" lower="${-pi*6.0}" upper="${pi*6.0}" />
  </joint>
  <link name="$(arg prefix)rear_wheel_steer_link">
    <visual>
      <origin xyz="0 0 0" rpy="0 0 0" />
      <geometry>
        <mesh filename="${meshes_file_direction}/rear_wheel_steer_link.stl" scale="0.001 0.001 0.001" />
      </geometry>
      <material name="silver">
        <color rgba="0.75 0.75 0.75 1"/>
      </material>
    </visual>
    <collision>
      <origin xyz="0 0 0" rpy="0 0 0" />
      <geometry>
        <mesh filename="${meshes_file_direction}/rear_wheel_steer_link.stl" scale="0.001 0.001 0.001" />
      </geometry>
    </collision>
  </link>
  <joint name="$(arg prefix)rear_wheel_drive" type="revolute">
      <parent link="$(arg prefix)rear_wheel_steer_link"/>
      <child link="$(arg prefix)rear_wheel_drive_link"/>
      <origin xyz="0 0 -0.18905" rpy="0 0 0"/>
      <axis xyz="0 1 0" />
      <limit velocity="4.8" effort="1" lower="${-pi*6.0}" upper="${pi*6.0}" />
  </joint>
  <link name="$(arg prefix)rear_wheel_drive_link">
    <visual>
      <origin xyz="0 0 0" rpy="0 0 0" />
      <geometry>
        <mesh filename="${meshes_file_direction}/rear_wheel_drive_link.stl" scale="0.001 0.001 0.001" />
      </geometry>
      <material name="silver">
        <color rgba="0.75 0.75 0.75 1"/>
      </material>
    </visual>
    <collision>
      <origin xyz="0 0 0" rpy="0 0 0" />
      <geometry>
        <mesh filename="${meshes_file_direction}/rear_wheel_drive_link.stl" scale="0.001 0.001 0.001" />
      </geometry>
    </collision>
  </link>

  <xacro:ffw_sg2_follower_system
    use_sim="$(arg use_sim)"
    use_fake_hardware="$(arg use_fake_hardware)"
    fake_sensor_commands="$(arg fake_sensor_commands)"/>

  <xacro:ffw_sg2_base_system
    use_sim="$(arg use_sim)"
    use_fake_hardware="$(arg use_fake_hardware)"
    fake_sensor_commands="$(arg fake_sensor_commands)"/>

  <gazebo>
      <plugin filename="gz_ros2_control-system" name="gz_ros2_control::GazeboSimROS2ControlPlugin">
        <parameters>$(find ffw_bringup)/config/$(arg model)/ffw_sg2_follower_ai_hardware_controller.yaml</parameters>
      </plugin>
  </gazebo>

</robot>
