<?xml version="1.0" ?>
<!-- =================================================================================== -->
<!-- |    This document was autogenerated by xacro from ffw_follower.urdf.xacro        | -->
<!-- |    EDITING THIS FILE BY HAND IS NOT RECOMMENDED                                 | -->
<!-- =================================================================================== -->
<robot name="ffw">
  <link name="base_link">
    <visual>
      <origin rpy="0 0 0" xyz="0 0 0"/>
      <geometry>
        <mesh filename="package://ffw_description/meshes/follower/base_mobile_assy.stl" scale="0.001 0.001 0.001"/>
      </geometry>
      <material name="grey">
        <color rgba="0.2 0.2 0.2 1"/>
      </material>
    </visual>
    <collision>
      <origin rpy="0 0 0" xyz="0 0 0"/>
      <geometry>
        <mesh filename="package://ffw_description/meshes/follower/base_mobile_assy.stl" scale="0.001 0.001 0.001"/>
      </geometry>
    </collision>
    <inertial>
      <origin xyz="-4.215593900e-02 1.414784900e-03 5.544221100e-01"/>
      <mass value="7.208755500e+01"/>
      <inertia ixx="2.239045300e+01" ixy="-1.263524100e-02" ixz="2.036407800e+00" iyy="2.283017500e+01" iyz="3.941520900e-02" izz="2.211418500e+00"/>
    </inertial>
  </link>
  <joint name="linear_joint" type="prismatic">
    <parent link="base_link"/>
    <child link="arm_base_link"/>
    <origin rpy="0 0 0" xyz="0.053 0 1.2096"/>
    <axis xyz="0 0 1"/>
    <limit effort="1000" lower="0.0" upper="0.25" velocity="4.8"/>
    <dynamics damping="0.1"/>
  </joint>
  <link name="arm_base_link">
    <visual>
      <origin rpy="0 0 0" xyz="0 0 0"/>
      <geometry>
        <mesh filename="package://ffw_description/meshes/follower/body_arm_assy.stl" scale="0.001 0.001 0.001"/>
      </geometry>
      <material name="grey">
        <color rgba="0.2 0.2 0.2 1"/>
      </material>
    </visual>
    <collision>
      <origin rpy="0 0 0" xyz="0 0 0"/>
      <geometry>
        <mesh filename="package://ffw_description/meshes/follower/body_arm_assy.stl" scale="0.001 0.001 0.001"/>
      </geometry>
    </collision>
    <inertial>
      <origin xyz="-4.607316100e-02 -2.281005300e-05 -2.702082100e-02"/>
      <mass value="8.721758400e+00"/>
      <inertia ixx="9.316905600e-02" ixy="1.223827600e-05" ixz="-1.109867300e-02" iyy="5.761433200e-02" iyz="-1.525995300e-05" izz="9.659478800e-02"/>
    </inertial>
  </link>
  <joint name="neck_joint1" type="revolute">
    <parent link="arm_base_link"/>
    <child link="neck_link1"/>
    <origin rpy="0 0 0" xyz="0.019 0 0.06475"/>
    <axis xyz="0 1 0"/>
    <limit effort="1000" lower="0.0" upper="0.4" velocity="4.8"/>
    <dynamics damping="0.1"/>
  </joint>
  <link name="neck_link1">
    <visual>
      <origin rpy="0 0 0" xyz="0 0 0"/>
      <geometry>
        <mesh filename="package://ffw_description/meshes/follower/neck_link1.stl" scale="0.001 0.001 0.001"/>
      </geometry>
      <material name="grey">
        <color rgba="0.2 0.2 0.2 1"/>
      </material>
    </visual>
    <collision>
      <origin rpy="0 0 0" xyz="0 0 0"/>
      <geometry>
        <mesh filename="package://ffw_description/meshes/follower/neck_link1.stl" scale="0.001 0.001 0.001"/>
      </geometry>
    </collision>
    <inertial>
      <origin xyz="-7.329875400e-03 0.000000000e+00 4.343627400e-02"/>
      <mass value="1.394727200e-01"/>
      <inertia ixx="5.752068900e-05" ixy="0.000000000e+00" ixz="4.943420800e-06" iyy="6.544451100e-05" iyz="0.000000000e+00" izz="5.003265300e-05"/>
    </inertial>
  </link>
  <joint name="neck_joint2" type="revolute">
    <parent link="neck_link1"/>
    <child link="neck_link2"/>
    <origin rpy="0 0 0" xyz="0 0 0.0475"/>
    <axis xyz="0 0 1"/>
    <limit effort="1000" lower="-0.6" upper="0.6" velocity="4.8"/>
    <dynamics damping="0.1"/>
  </joint>
  <link name="neck_link2">
    <visual>
      <origin rpy="0 0 0" xyz="0 0 0"/>
      <geometry>
        <mesh filename="package://ffw_description/meshes/follower/neck_link2.stl" scale="0.001 0.001 0.001"/>
      </geometry>
      <material name="grey">
        <color rgba="0.2 0.2 0.2 1"/>
      </material>
    </visual>
    <collision>
      <origin rpy="0 0 0" xyz="0 0 0"/>
      <geometry>
        <mesh filename="package://ffw_description/meshes/follower/neck_link2.stl" scale="0.001 0.001 0.001"/>
      </geometry>
    </collision>
    <inertial>
      <origin xyz="8.779073500e-03 -8.403922700e-05 4.254319200e-02"/>
      <mass value="1.450781500e-01"/>
      <inertia ixx="1.834982400e-04" ixy="-4.755711300e-08" ixz="-3.507748300e-06" iyy="2.283875600e-05" iyz="-2.683629200e-08" izz="1.834735800e-04"/>
    </inertial>
  </link>
  <joint name="arm_r_joint1" type="revolute">
    <parent link="arm_base_link"/>
    <child link="arm_r_link1"/>
    <origin rpy="0 0 0" xyz="0 -0.1025 0"/>
    <axis xyz="0 1 0"/>
    <limit effort="1000" lower="-3.14" upper="3.14" velocity="4.8"/>
    <dynamics damping="0.1"/>
  </joint>
  <link name="arm_r_link1">
    <visual>
      <origin rpy="0 0 0" xyz="0 0 0"/>
      <geometry>
        <mesh filename="package://ffw_description/meshes/follower/arm_r_link1.stl" scale="0.001 0.001 0.001"/>
      </geometry>
      <material name="black">
        <color rgba="0.2 0.2 0.2 1"/>
      </material>
    </visual>
    <collision>
      <origin rpy="0 0 0" xyz="0 0 0"/>
      <geometry>
        <mesh filename="package://ffw_description/meshes/follower/arm_r_link1.stl" scale="0.001 0.001 0.001"/>
      </geometry>
    </collision>
    <inertial>
      <origin xyz="1.624540100e-02 -1.150833200e-01 -1.160152700e-04"/>
      <mass value="1.933953700e+00"/>
      <inertia ixx="2.404191600e-03" ixy="2.572789100e-04" ixz="-1.117177300e-05" iyy="2.564101300e-03" iyz="-2.413538900e-06" izz="3.056035500e-03"/>
    </inertial>
  </link>
  <joint name="arm_r_joint2" type="revolute">
    <parent link="arm_r_link1"/>
    <child link="arm_r_link2"/>
    <origin rpy="0 0 0" xyz="0 -0.123 0"/>
    <axis xyz="-1 0 0"/>
    <limit effort="1000" lower="0" upper="3.14" velocity="4.8"/>
    <dynamics damping="0.1"/>
  </joint>
  <link name="arm_r_link2">
    <visual>
      <origin rpy="0 0 0" xyz="0 0 0"/>
      <geometry>
        <mesh filename="package://ffw_description/meshes/follower/arm_r_link2.stl" scale="0.001 0.001 0.001"/>
      </geometry>
      <material name="black">
        <color rgba="0.2 0.2 0.2 1"/>
      </material>
    </visual>
    <collision>
      <origin rpy="0 0 0" xyz="0 0 0"/>
      <geometry>
        <mesh filename="package://ffw_description/meshes/follower/arm_r_link2.stl" scale="0.001 0.001 0.001"/>
      </geometry>
    </collision>
    <inertial>
      <origin xyz="9.040963900e-03 1.058016600e-04 -1.440332700e-01"/>
      <mass value="2.124140800e+00"/>
      <inertia ixx="9.942940500e-03" ixy="2.652646000e-06" ixz="-2.364645000e-03" iyy="1.085582700e-02" iyz="-4.964042700e-06" izz="3.164856100e-03"/>
    </inertial>
  </link>
  <joint name="arm_r_joint3" type="revolute">
    <parent link="arm_r_link2"/>
    <child link="arm_r_link3"/>
    <origin rpy="0 0 0" xyz="0 0 -0.165"/>
    <axis xyz="0 0 -1"/>
    <limit effort="1000" lower="-1.57" upper="1.57" velocity="4.8"/>
    <dynamics damping="0.1"/>
  </joint>
  <link name="arm_r_link3">
    <visual>
      <origin rpy="0 0 0" xyz="0 0 0"/>
      <geometry>
        <mesh filename="package://ffw_description/meshes/follower/arm_r_link3.stl" scale="0.001 0.001 0.001"/>
      </geometry>
      <material name="black">
        <color rgba="0.2 0.2 0.2 1"/>
      </material>
    </visual>
    <collision>
      <origin rpy="0 0 0" xyz="0 0 0"/>
      <geometry>
        <mesh filename="package://ffw_description/meshes/follower/arm_r_link3.stl" scale="0.001 0.001 0.001"/>
      </geometry>
    </collision>
    <inertial>
      <origin xyz="-2.510915300e-05 -1.794721700e-02 -1.087648400e-01"/>
      <mass value="1.407742700e+00"/>
      <inertia ixx="1.932711900e-03" ixy="2.160084900e-06" ixz="-3.401052700e-07" iyy="1.448297100e-03" iyz="-2.117341800e-04" izz="1.573054500e-03"/>
    </inertial>
  </link>
  <joint name="arm_r_joint4" type="revolute">
    <parent link="arm_r_link3"/>
    <child link="arm_r_link4"/>
    <origin rpy="0 0 0" xyz="0 0 -0.117"/>
    <axis xyz="0 1 0"/>
    <limit effort="1000" lower="-1.86" upper="1.86" velocity="4.8"/>
    <dynamics damping="0.1"/>
  </joint>
  <link name="arm_r_link4">
    <visual>
      <origin rpy="0 0 0" xyz="0 0 0"/>
      <geometry>
        <mesh filename="package://ffw_description/meshes/follower/arm_r_link4.stl" scale="0.001 0.001 0.001"/>
      </geometry>
      <material name="black">
        <color rgba="0.2 0.2 0.2 1"/>
      </material>
    </visual>
    <collision>
      <origin rpy="0 0 0" xyz="0 0 0"/>
      <geometry>
        <mesh filename="package://ffw_description/meshes/follower/arm_r_link4.stl" scale="0.001 0.001 0.001"/>
      </geometry>
    </collision>
    <inertial>
      <origin xyz="4.397034900e-05 -9.787357900e-03 -1.378883000e-01"/>
      <mass value="1.513136300e+00"/>
      <inertia ixx="6.362933700e-03" ixy="-6.975489100e-07" ixz="-1.270290600e-06" iyy="5.687568700e-03" iyz="1.606295500e-03" izz="1.926640600e-03"/>
    </inertial>
  </link>
  <joint name="arm_r_joint5" type="revolute">
    <parent link="arm_r_link4"/>
    <child link="arm_r_link5"/>
    <origin rpy="0 0 0" xyz="0 0 -0.1559"/>
    <axis xyz="0 0 -1"/>
    <limit effort="1000" lower="-1.57" upper="1.57" velocity="4.8"/>
    <dynamics damping="0.1"/>
  </joint>
  <link name="arm_r_link5">
    <visual>
      <origin rpy="0 0 0" xyz="0 0 0"/>
      <geometry>
        <mesh filename="package://ffw_description/meshes/follower/arm_r_link5.stl" scale="0.001 0.001 0.001"/>
      </geometry>
      <material name="black">
        <color rgba="0.2 0.2 0.2 1"/>
      </material>
    </visual>
    <collision>
      <origin rpy="0 0 0" xyz="0 0 0"/>
      <geometry>
        <mesh filename="package://ffw_description/meshes/follower/arm_r_link5.stl" scale="0.001 0.001 0.001"/>
      </geometry>
    </collision>
    <inertial>
      <origin xyz="-2.629623700e-05 -1.879570800e-02 -9.838709700e-02"/>
      <mass value="1.344193200e+00"/>
      <inertia ixx="1.697614400e-03" ixy="1.382419000e-06" ixz="-2.509507400e-07" iyy="1.234418100e-03" iyz="-1.480093000e-04" izz="1.504563200e-03"/>
    </inertial>
  </link>
  <joint name="arm_r_joint6" type="revolute">
    <parent link="arm_r_link5"/>
    <child link="arm_r_link6"/>
    <origin rpy="0 0 0" xyz="0 0 -0.1041"/>
    <axis xyz="0 1 0"/>
    <limit effort="1000" lower="-1.57" upper="1.57" velocity="4.8"/>
    <dynamics damping="0.1"/>
  </joint>
  <link name="arm_r_link6">
    <visual>
      <origin rpy="0 0 0" xyz="0 0 0"/>
      <geometry>
        <mesh filename="package://ffw_description/meshes/follower/arm_r_link6.stl" scale="0.001 0.001 0.001"/>
      </geometry>
      <material name="black">
        <color rgba="0.2 0.2 0.2 1"/>
      </material>
    </visual>
    <collision>
      <origin rpy="0 0 0" xyz="0 0 0"/>
      <geometry>
        <mesh filename="package://ffw_description/meshes/follower/arm_r_link6.stl" scale="0.001 0.001 0.001"/>
      </geometry>
    </collision>
    <inertial>
      <origin xyz="3.398392800e-04 -1.943041700e-02 -6.394589600e-02"/>
      <mass value="6.362337700e-01"/>
      <inertia ixx="1.388961300e-03" ixy="-4.201514200e-06" ixz="5.358941000e-06" iyy="1.086005700e-03" iyz="5.260231200e-04" izz="9.664532300e-04"/>
    </inertial>
  </link>
  <joint name="arm_r_joint7" type="revolute">
    <parent link="arm_r_link6"/>
    <child link="arm_r_link7"/>
    <origin rpy="0 0 0" xyz="0 0 -0.0885"/>
    <axis xyz="-1 0 0"/>
    <limit effort="1000" lower="-1.046" upper="1.046" velocity="4.8"/>
    <dynamics damping="0.1"/>
  </joint>
  <link name="arm_r_link7">
    <visual>
      <origin rpy="0 0 0" xyz="0 0 0"/>
      <geometry>
        <mesh filename="package://ffw_description/meshes/follower/arm_r_link7.stl" scale="0.001 0.001 0.001"/>
      </geometry>
      <material name="black">
        <color rgba="0.2 0.2 0.2 1"/>
      </material>
    </visual>
    <collision>
      <origin rpy="0 0 0" xyz="0 0 0"/>
      <geometry>
        <mesh filename="package://ffw_description/meshes/follower/arm_r_link7.stl" scale="0.001 0.001 0.001"/>
      </geometry>
    </collision>
    <inertial>
      <origin xyz="-7.379093300e-03 0.000000000e+00 -2.559652800e-02"/>
      <mass value="1.243248700e-01"/>
      <inertia ixx="5.998355100e-05" ixy="0.000000000e+00" ixz="2.451378300e-05" iyy="1.746288100e-04" iyz="0.000000000e+00" izz="1.606692600e-04"/>
    </inertial>
  </link>
  <joint name="arm_l_joint1" type="revolute">
    <parent link="arm_base_link"/>
    <child link="arm_l_link1"/>
    <origin rpy="0 0 0" xyz="0 0.1025 0"/>
    <axis xyz="0 1 0"/>
    <limit effort="1000" lower="-3.14" upper="3.14" velocity="4.8"/>
    <dynamics damping="0.1"/>
  </joint>
  <link name="arm_l_link1">
    <visual>
      <origin rpy="0 0 0" xyz="0 0 0"/>
      <geometry>
        <mesh filename="package://ffw_description/meshes/follower/arm_l_link1.stl" scale="0.001 0.001 0.001"/>
      </geometry>
      <material name="black">
        <color rgba="0.2 0.2 0.2 1"/>
      </material>
    </visual>
    <collision>
      <origin rpy="0 0 0" xyz="0 0 0"/>
      <geometry>
        <mesh filename="package://ffw_description/meshes/follower/arm_l_link1.stl" scale="0.001 0.001 0.001"/>
      </geometry>
    </collision>
    <inertial>
      <origin xyz="1.625390900e-02 1.150971200e-01 1.160152700e-04"/>
      <mass value="1.933953700e+00"/>
      <inertia ixx="2.404898000e-03" ixy="-2.558530200e-04" ixz="1.123409700e-05" iyy="2.562086300e-03" iyz="-2.410406700e-06" izz="3.054703500e-03"/>
    </inertial>
  </link>
  <joint name="arm_l_joint2" type="revolute">
    <parent link="arm_l_link1"/>
    <child link="arm_l_link2"/>
    <origin rpy="0 0 0" xyz="0 0.123 0"/>
    <axis xyz="1 0 0"/>
    <limit effort="1000" lower="0.0" upper="3.14" velocity="4.8"/>
    <dynamics damping="0.1"/>
  </joint>
  <link name="arm_l_link2">
    <visual>
      <origin rpy="0 0 0" xyz="0 0 0"/>
      <geometry>
        <mesh filename="package://ffw_description/meshes/follower/arm_l_link2.stl" scale="0.001 0.001 0.001"/>
      </geometry>
      <material name="black">
        <color rgba="0.2 0.2 0.2 1"/>
      </material>
    </visual>
    <collision>
      <origin rpy="0 0 0" xyz="0 0 0"/>
      <geometry>
        <mesh filename="package://ffw_description/meshes/follower/arm_l_link2.stl" scale="0.001 0.001 0.001"/>
      </geometry>
    </collision>
    <inertial>
      <origin xyz="9.096806400e-03 -1.055040600e-04 -1.440332700e-01"/>
      <mass value="2.124140800e+00"/>
      <inertia ixx="9.942940700e-03" ixy="-1.417843000e-06" ixz="-2.368306000e-03" iyy="1.085364600e-02" iyz="4.864401200e-06" izz="3.162675400e-03"/>
    </inertial>
  </link>
  <joint name="arm_l_joint3" type="revolute">
    <parent link="arm_l_link2"/>
    <child link="arm_l_link3"/>
    <origin rpy="0 0 0" xyz="0 0 -0.165"/>
    <axis xyz="0 0 1"/>
    <limit effort="1000" lower="-6.28" upper="6.28" velocity="4.8"/>
    <dynamics damping="0.1"/>
  </joint>
  <link name="arm_l_link3">
    <visual>
      <origin rpy="0 0 0" xyz="0 0 0"/>
      <geometry>
        <mesh filename="package://ffw_description/meshes/follower/arm_l_link3.stl" scale="0.001 0.001 0.001"/>
      </geometry>
      <material name="black">
        <color rgba="0.2 0.2 0.2 1"/>
      </material>
    </visual>
    <collision>
      <origin rpy="0 0 0" xyz="0 0 0"/>
      <geometry>
        <mesh filename="package://ffw_description/meshes/follower/arm_l_link3.stl" scale="0.001 0.001 0.001"/>
      </geometry>
    </collision>
    <inertial>
      <origin xyz="2.510915400e-05 1.794721700e-02 -1.087573700e-01"/>
      <mass value="1.407742700e+00"/>
      <inertia ixx="1.933549600e-03" ixy="1.416541700e-06" ixz="3.403693800e-07" iyy="1.449111500e-03" iyz="2.119230000e-04" izz="1.573054500e-03"/>
    </inertial>
  </link>
  <joint name="arm_l_joint4" type="revolute">
    <parent link="arm_l_link3"/>
    <child link="arm_l_link4"/>
    <origin rpy="0 0 0" xyz="0 0 -0.117"/>
    <axis xyz="0 1 0"/>
    <limit effort="1000" lower="-1.86" upper="1.86" velocity="4.8"/>
    <dynamics damping="0.1"/>
  </joint>
  <link name="arm_l_link4">
    <visual>
      <origin rpy="0 0 0" xyz="0 0 0"/>
      <geometry>
        <mesh filename="package://ffw_description/meshes/follower/arm_l_link4.stl" scale="0.001 0.001 0.001"/>
      </geometry>
      <material name="black">
        <color rgba="0.2 0.2 0.2 1"/>
      </material>
    </visual>
    <collision>
      <origin rpy="0 0 0" xyz="0 0 0"/>
      <geometry>
        <mesh filename="package://ffw_description/meshes/follower/arm_l_link4.stl" scale="0.001 0.001 0.001"/>
      </geometry>
    </collision>
    <inertial>
      <origin xyz="-4.397034900e-05 9.787041900e-03 -1.378883000e-01"/>
      <mass value="1.513136300e+00"/>
      <inertia ixx="6.362873000e-03" ixy="-6.975278900e-07" ixz="1.270290600e-06" iyy="5.687568700e-03" iyz="-1.606244800e-03" izz="1.926579800e-03"/>
    </inertial>
  </link>
  <joint name="arm_l_joint5" type="revolute">
    <parent link="arm_l_link4"/>
    <child link="arm_l_link5"/>
    <origin rpy="0 0 0" xyz="0 0 -0.1559"/>
    <axis xyz="0 0 1"/>
    <limit effort="1000" lower="-1.57" upper="1.57" velocity="4.8"/>
    <dynamics damping="0.1"/>
  </joint>
  <link name="arm_l_link5">
    <visual>
      <origin rpy="0 0 0" xyz="0 0 0"/>
      <geometry>
        <mesh filename="package://ffw_description/meshes/follower/arm_l_link5.stl" scale="0.001 0.001 0.001"/>
      </geometry>
      <material name="black">
        <color rgba="0.2 0.2 0.2 1"/>
      </material>
    </visual>
    <collision>
      <origin rpy="0 0 0" xyz="0 0 0"/>
      <geometry>
        <mesh filename="package://ffw_description/meshes/follower/arm_l_link5.stl" scale="0.001 0.001 0.001"/>
      </geometry>
    </collision>
    <inertial>
      <origin xyz="-4.953061500e-05 1.879570900e-02 -9.836393300e-02"/>
      <mass value="1.344193200e+00"/>
      <inertia ixx="1.699126800e-03" ixy="-3.352286000e-06" ixz="-4.262511700e-07" iyy="1.234144700e-03" iyz="1.491721400e-04" izz="1.502606200e-03"/>
    </inertial>
  </link>
  <joint name="arm_l_joint6" type="revolute">
    <parent link="arm_l_link5"/>
    <child link="arm_l_link6"/>
    <origin rpy="0 0 0" xyz="0 0 -0.1041"/>
    <axis xyz="0 1 0"/>
    <limit effort="1000" lower="-1.57" upper="1.57" velocity="4.8"/>
    <dynamics damping="0.1"/>
  </joint>
  <link name="arm_l_link6">
    <visual>
      <origin rpy="0 0 0" xyz="0 0 0"/>
      <geometry>
        <mesh filename="package://ffw_description/meshes/follower/arm_l_link6.stl" scale="0.001 0.001 0.001"/>
      </geometry>
      <material name="black">
        <color rgba="0.2 0.2 0.2 1"/>
      </material>
    </visual>
    <collision>
      <origin rpy="0 0 0" xyz="0 0 0"/>
      <geometry>
        <mesh filename="package://ffw_description/meshes/follower/arm_l_link6.stl" scale="0.001 0.001 0.001"/>
      </geometry>
    </collision>
    <inertial>
      <origin xyz="3.844904400e-04 1.942979300e-02 -6.394564400e-02"/>
      <mass value="6.362337700e-01"/>
      <inertia ixx="1.388910800e-03" ixy="4.568060400e-06" ixz="5.660750700e-06" iyy="1.086005700e-03" iyz="-5.260047400e-04" izz="9.664181300e-04"/>
    </inertial>
  </link>
  <joint name="arm_l_joint7" type="revolute">
    <parent link="arm_l_link6"/>
    <child link="arm_l_link7"/>
    <origin rpy="0 0 0" xyz="0 0 -0.0885"/>
    <axis xyz="1 0 0"/>
    <limit effort="1000" lower="-1.046" upper="1.046" velocity="4.8"/>
    <dynamics damping="0.1"/>
  </joint>
  <link name="arm_l_link7">
    <visual>
      <origin rpy="0 0 0" xyz="0 0 0"/>
      <geometry>
        <mesh filename="package://ffw_description/meshes/follower/arm_l_link7.stl" scale="0.001 0.001 0.001"/>
      </geometry>
      <material name="black">
        <color rgba="0.2 0.2 0.2 1"/>
      </material>
    </visual>
    <collision>
      <origin rpy="0 0 0" xyz="0 0 0"/>
      <geometry>
        <mesh filename="package://ffw_description/meshes/follower/arm_l_link7.stl" scale="0.001 0.001 0.001"/>
      </geometry>
    </collision>
    <inertial>
      <origin xyz="-7.210928100e-03 0.000000000e+00 -2.560159000e-02"/>
      <mass value="1.243248700e-01"/>
      <inertia ixx="5.994976500e-05" ixy="0.000000000e+00" ixz="2.416233500e-05" iyy="1.738725800e-04" iyz="0.000000000e+00" izz="1.599468200e-04"/>
    </inertial>
  </link>
  <!-- Import control_xacro -->
  <link name="base_link_left_hand">
    <inertial>
      <origin rpy="0 0 0" xyz="-5.81855257230368E-05 0.0036855956860619 -0.0826153899028331"/>
      <mass value="0.260034351097693"/>
      <inertia ixx="0.000223659755666589" ixy="-1.13436481934473E-06" ixz="5.34309354519849E-07" iyy="0.000266799681483547" iyz="1.40944118648867E-05" izz="0.000132857769181899"/>
    </inertial>
    <visual>
      <origin rpy="0 0 0" xyz="0 0 0"/>
      <geometry>
        <mesh filename="package://ffw_description/meshes/left_hand/base_link.STL"/>
      </geometry>
      <material name="">
        <color rgba="0.792156862745098 0.819607843137255 0.933333333333333 1"/>
      </material>
    </visual>
    <collision>
      <origin rpy="0 0 0" xyz="0 0 0"/>
      <geometry>
        <mesh filename="package://ffw_description/meshes/left_hand/base_link.STL"/>
      </geometry>
    </collision>
  </link>
  <link name="left_thumb_1">
    <inertial>
      <origin rpy="0 0 0" xyz="0.00178423404495211 -0.000649404577309123 -0.0031358931043441"/>
      <mass value="0.00115518743162309"/>
      <inertia ixx="5.98912200501135E-08" ixy="-8.04315731947437E-09" ixz="-3.29346919841095E-09" iyy="4.07201234589857E-08" iyz="1.19872544716431E-09" izz="6.18161684388651E-08"/>
    </inertial>
    <visual>
      <origin rpy="0 0 0" xyz="0 0 0"/>
      <geometry>
        <mesh filename="package://ffw_description/meshes/left_hand/left_thumb_1.STL"/>
      </geometry>
      <material name="">
        <color rgba="0.792156862745098 0.819607843137255 0.933333333333333 1"/>
      </material>
    </visual>
    <collision>
      <origin rpy="0 0 0" xyz="0 0 0"/>
      <geometry>
        <mesh filename="package://ffw_description/meshes/left_hand/left_thumb_1.STL"/>
      </geometry>
    </collision>
  </link>
  <joint name="left_thumb_1_joint" type="revolute">
    <origin rpy="0 0 0" xyz="0.0269 -0.02101 -0.07075"/>
    <parent link="base_link_left_hand"/>
    <child link="left_thumb_1"/>
    <axis xyz="0 0 -1"/>
    <limit effort="10" lower="0" upper="1.15" velocity="1"/>
  </joint>
  <link name="left_thumb_2">
    <inertial>
      <origin rpy="0 0 0" xyz="0.0141077165126408 0.013272947664556 0.00905027694248729"/>
      <mass value="0.016"/>
      <inertia ixx="1.06585698719649E-06" ixy="-7.62263321516971E-08" ixz="2.95033226564006E-11" iyy="1.06558155578278E-06" iyz="1.55271585897891E-11" izz="1.39709651951733E-06"/>
    </inertial>
    <visual>
      <origin rpy="0 0 0" xyz="0 0 0"/>
      <geometry>
        <mesh filename="package://ffw_description/meshes/left_hand/left_thumb_2.STL"/>
      </geometry>
      <material name="">
        <color rgba="0.792156862745098 0.819607843137255 0.933333333333333 1"/>
      </material>
    </visual>
    <collision>
      <origin rpy="0 0 0" xyz="0 0 0"/>
      <geometry>
        <mesh filename="package://ffw_description/meshes/left_hand/left_thumb_2.STL"/>
      </geometry>
    </collision>
  </link>
  <joint name="left_thumb_2_joint" type="revolute">
    <origin rpy="-1.5708 0 -0.34907" xyz="0.0063016 -0.011924 -0.00125"/>
    <parent link="left_thumb_1"/>
    <child link="left_thumb_2"/>
    <axis xyz="0 0 1"/>
    <limit effort="10" lower="0" upper="0.55" velocity="1"/>
  </joint>
  <link name="left_thumb_3">
    <inertial>
      <origin rpy="0 0 0" xyz="0.0175210608796189 -0.000458783419545392 0.00589186777098984"/>
      <mass value="0.012"/>
      <inertia ixx="4.67948369620491E-07" ixy="-4.4974688607358E-08" ixz="1.01425359574474E-11" iyy="3.98794196148187E-07" iyz="2.07037920898898E-10" izz="4.24723917424999E-07"/>
    </inertial>
    <visual>
      <origin rpy="0 0 0" xyz="0 0 0"/>
      <geometry>
        <mesh filename="package://ffw_description/meshes/left_hand/left_thumb_3.STL"/>
      </geometry>
      <material name="">
        <color rgba="0.792156862745098 0.819607843137255 0.933333333333333 1"/>
      </material>
    </visual>
    <collision>
      <origin rpy="0 0 0" xyz="0 0 0"/>
      <geometry>
        <mesh filename="package://ffw_description/meshes/left_hand/left_thumb_3.STL"/>
      </geometry>
    </collision>
  </link>
  <joint name="left_thumb_3_joint" type="revolute">
    <origin rpy="0 0 0" xyz="0.026828 0.02583 0.00315"/>
    <parent link="left_thumb_2"/>
    <child link="left_thumb_3"/>
    <axis xyz="0 0 1"/>
    <limit effort="10" lower="0" upper="3.14" velocity="1"/>
    <mimic joint="left_thumb_2_joint" multiplier="0.60" offset="0"/>
  </joint>
  <link name="left_thumb_4">
    <inertial>
      <origin rpy="0 0 0" xyz="0.0159972574626049 0.0063105797700872 0.0073433144647696"/>
      <mass value="0.01"/>
      <inertia ixx="6.4362640059723E-07" ixy="-2.57376746969386E-07" ixz="-8.63129696542143E-10" iyy="7.63678708562786E-07" iyz="-7.21288836303217E-10" izz="9.2570163408105E-07"/>
    </inertial>
    <visual>
      <origin rpy="0 0 0" xyz="0 0 0"/>
      <geometry>
        <mesh filename="package://ffw_description/meshes/left_hand/left_thumb_4.STL"/>
      </geometry>
      <material name="">
        <color rgba="0.792156862745098 0.819607843137255 0.933333333333333 1"/>
      </material>
    </visual>
    <collision>
      <origin rpy="0 0 0" xyz="0 0 0"/>
      <geometry>
        <mesh filename="package://ffw_description/meshes/left_hand/left_thumb_4.STL"/>
      </geometry>
    </collision>
  </link>
  <joint name="left_thumb_4_joint" type="revolute">
    <origin rpy="0 0 0" xyz="0.027027 0.0069965 -0.00145"/>
    <parent link="left_thumb_3"/>
    <child link="left_thumb_4"/>
    <axis xyz="0 0 1"/>
    <limit effort="10" lower="0" upper="3.14" velocity="1"/>
    <mimic joint="left_thumb_2_joint" multiplier="0.8" offset="0"/>
  </joint>
  <link name="left_index_1">
    <inertial>
      <origin rpy="0 0 0" xyz="-0.00183599258071257 0.0123544163382434 -0.00665152565125451"/>
      <mass value="0.0071995003148682"/>
      <inertia ixx="1.28363093823079E-06" ixy="4.22091506924093E-08" ixz="-1.1741465013013E-12" iyy="5.79447850871435E-07" iyz="-8.63816965731366E-11" izz="1.32914845722975E-06"/>
    </inertial>
    <visual>
      <origin rpy="0 0 0" xyz="0 0 0"/>
      <geometry>
        <mesh filename="package://ffw_description/meshes/left_hand/left_index_1.STL"/>
      </geometry>
      <material name="">
        <color rgba="0.792156862745098 0.819607843137255 0.933333333333333 1"/>
      </material>
    </visual>
    <collision>
      <origin rpy="0 0 0" xyz="0 0 0"/>
      <geometry>
        <mesh filename="package://ffw_description/meshes/left_hand/left_index_1.STL"/>
      </geometry>
    </collision>
  </link>
  <joint name="left_index_1_joint" type="revolute">
    <origin rpy="-1.6057 0 1.5708" xyz="0.025387 -0.00056467 -0.15686"/>
    <parent link="base_link_left_hand"/>
    <child link="left_index_1"/>
    <axis xyz="0 0 1"/>
    <limit effort="10" lower="0" upper="1.6" velocity="1"/>
  </joint>
  <link name="left_index_2">
    <inertial>
      <origin rpy="0 0 0" xyz="0.000405420051948283 0.0257003783460073 -0.00610830787560272"/>
      <mass value="0.00968688267109518"/>
      <inertia ixx="2.25563043691857E-06" ixy="4.11282885240034E-07" ixz="3.87338024122588E-10" iyy="3.91279806505403E-07" iyz="-2.76559043550419E-09" izz="2.30247359295784E-06"/>
    </inertial>
    <visual>
      <origin rpy="0 0 0" xyz="0 0 0"/>
      <geometry>
        <mesh filename="package://ffw_description/meshes/left_hand/left_index_2.STL"/>
      </geometry>
      <material name="">
        <color rgba="0.792156862745098 0.819607843137255 0.933333333333333 1"/>
      </material>
    </visual>
    <collision>
      <origin rpy="0 0 0" xyz="0 0 0"/>
      <geometry>
        <mesh filename="package://ffw_description/meshes/left_hand/left_index_2.STL"/>
      </geometry>
    </collision>
  </link>
  <joint name="left_index_2_joint" type="revolute">
    <origin rpy="0 0 0" xyz="-0.0016312 0.032734 -0.00055"/>
    <parent link="left_index_1"/>
    <child link="left_index_2"/>
    <axis xyz="0 0 1"/>
    <limit effort="10" lower="0" upper="3.14" velocity="1"/>
    <mimic joint="left_index_1_joint" multiplier="1.05" offset="0"/>
  </joint>
  <link name="left_middle_1">
    <inertial>
      <origin rpy="0 0 0" xyz="-0.00229271394242232 0.0122778605414752 -0.00665151068667683"/>
      <mass value="0.00719950322487974"/>
      <inertia ixx="1.27951858905779E-06" ixy="6.81813021711596E-08" ixz="1.58551121583499E-12" iyy="5.83543537428452E-07" iyz="-8.56179612608701E-11" izz="1.32913234511164E-06"/>
    </inertial>
    <visual>
      <origin rpy="0 0 0" xyz="0 0 0"/>
      <geometry>
        <mesh filename="package://ffw_description/meshes/left_hand/left_middle_1.STL"/>
      </geometry>
      <material name="">
        <color rgba="0.792156862745098 0.819607843137255 0.933333333333333 1"/>
      </material>
    </visual>
    <collision>
      <origin rpy="0 0 0" xyz="0 0 0"/>
      <geometry>
        <mesh filename="package://ffw_description/meshes/left_hand/left_middle_1.STL"/>
      </geometry>
    </collision>
  </link>
  <joint name="left_middle_1_joint" type="revolute">
    <origin rpy="-1.5708 0 1.5708" xyz="0.0037996 -0.00056467 -0.157"/>
    <parent link="base_link_left_hand"/>
    <child link="left_middle_1"/>
    <axis xyz="0 0 1"/>
    <limit effort="1" lower="0" upper="1.6" velocity="1"/>
  </joint>
  <link name="left_middle_2">
    <inertial>
      <origin rpy="0 0 0" xyz="7.51983994427274E-05 0.027448753770842 -0.00610022997575017"/>
      <mass value="0.0104611931926301"/>
      <inertia ixx="2.75831931773332E-06" ixy="4.66412841401028E-07" ixz="7.35766561775226E-12" iyy="4.22466538741155E-07" iyz="-1.79608426686769E-11" izz="2.80722617348706E-06"/>
    </inertial>
    <visual>
      <origin rpy="0 0 0" xyz="0 0 0"/>
      <geometry>
        <mesh filename="package://ffw_description/meshes/left_hand/left_middle_2.STL"/>
      </geometry>
      <material name="">
        <color rgba="0.792156862745098 0.819607843137255 0.933333333333333 1"/>
      </material>
    </visual>
    <collision>
      <origin rpy="0 0 0" xyz="0 0 0"/>
      <geometry>
        <mesh filename="package://ffw_description/meshes/left_hand/left_middle_2.STL"/>
      </geometry>
    </collision>
  </link>
  <joint name="left_middle_2_joint" type="revolute">
    <origin rpy="0 0 0" xyz="-0.0028436 0.032651 -0.00055"/>
    <parent link="left_middle_1"/>
    <child link="left_middle_2"/>
    <axis xyz="0 0 1"/>
    <limit effort="10" lower="0" upper="3.14" velocity="1"/>
    <mimic joint="left_middle_1_joint" multiplier="1.05" offset="0"/>
  </joint>
  <link name="left_ring_1">
    <inertial>
      <origin rpy="0 0 0" xyz="-0.00240530428455066 0.0122563079467745 -0.00665150968297497"/>
      <mass value="0.00719949770218712"/>
      <inertia ixx="1.27820682409824E-06" ixy="7.45572429780093E-08" ixz="2.25718181808859E-12" iyy="5.84853511073517E-07" iyz="-8.56222330411309E-11" izz="1.32913088941838E-06"/>
    </inertial>
    <visual>
      <origin rpy="0 0 0" xyz="0 0 0"/>
      <geometry>
        <mesh filename="package://ffw_description/meshes/left_hand/left_ring_1.STL"/>
      </geometry>
      <material name="">
        <color rgba="0.792156862745098 0.819607843137255 0.933333333333333 1"/>
      </material>
    </visual>
    <collision>
      <origin rpy="0 0 0" xyz="0 0 0"/>
      <geometry>
        <mesh filename="package://ffw_description/meshes/left_hand/left_ring_1.STL"/>
      </geometry>
    </collision>
  </link>
  <joint name="left_ring_1_joint" type="revolute">
    <origin rpy="-1.5184 0 1.5708" xyz="-0.017813 -0.00056467 -0.15614"/>
    <parent link="base_link_left_hand"/>
    <child link="left_ring_1"/>
    <axis xyz="0 0 1"/>
    <limit effort="10" lower="0" upper="1.6" velocity="1"/>
  </joint>
  <link name="left_ring_2">
    <inertial>
      <origin rpy="0 0 0" xyz="0.000667145407605998 0.0256949163202511 -0.00610829894053159"/>
      <mass value="0.00968685177133057"/>
      <inertia ixx="2.26381138740299E-06" ixy="3.92210300202205E-07" ixz="3.58404653503583E-10" iyy="3.83095000534084E-07" iyz="-2.77027363965469E-09" izz="2.30247104599333E-06"/>
    </inertial>
    <visual>
      <origin rpy="0 0 0" xyz="0 0 0"/>
      <geometry>
        <mesh filename="package://ffw_description/meshes/left_hand/left_ring_2.STL"/>
      </geometry>
      <material name="">
        <color rgba="0.792156862745098 0.819607843137255 0.933333333333333 1"/>
      </material>
    </visual>
    <collision>
      <origin rpy="0 0 0" xyz="0 0 0"/>
      <geometry>
        <mesh filename="package://ffw_description/meshes/left_hand/left_ring_2.STL"/>
      </geometry>
    </collision>
  </link>
  <joint name="left_ring_2_joint" type="revolute">
    <origin rpy="0 0 0" xyz="-0.0031431 0.032624 -0.00055"/>
    <parent link="left_ring_1"/>
    <child link="left_ring_2"/>
    <axis xyz="0 0 1"/>
    <limit effort="10" lower="0" upper="3.14" velocity="1"/>
    <mimic joint="left_ring_1_joint" multiplier="1.05" offset="0"/>
  </joint>
  <link name="left_little_1">
    <inertial>
      <origin rpy="0 0 0" xyz="-0.00316889023513399 0.0120814769898197 -0.00665148964848"/>
      <mass value="0.0071994553320001"/>
      <inertia ixx="1.26614239360362E-06" ixy="1.17349328114653E-07" ixz="6.69925886240907E-12" iyy="5.96905140854994E-07" iyz="-8.54914063893311E-11" izz="1.32912203576944E-06"/>
    </inertial>
    <visual>
      <origin rpy="0 0 0" xyz="0 0 0"/>
      <geometry>
        <mesh filename="package://ffw_description/meshes/left_hand/left_little_1.STL"/>
      </geometry>
      <material name="">
        <color rgba="0.792156862745098 0.819607843137255 0.933333333333333 1"/>
      </material>
    </visual>
    <collision>
      <origin rpy="0 0 0" xyz="0 0 0"/>
      <geometry>
        <mesh filename="package://ffw_description/meshes/left_hand/left_little_1.STL"/>
      </geometry>
    </collision>
  </link>
  <joint name="left_little_1_joint" type="revolute">
    <origin rpy="-1.4661 0 1.5708" xyz="-0.039144 -0.00056467 -0.15226"/>
    <parent link="base_link_left_hand"/>
    <child link="left_little_1"/>
    <axis xyz="0 0 1"/>
    <limit effort="10" lower="0" upper="1.6" velocity="1"/>
  </joint>
  <link name="left_little_2">
    <inertial>
      <origin rpy="0 0 0" xyz="0.00469503836926433 0.020441957551037 -0.0061004930536056"/>
      <mass value="0.00759267726265222"/>
      <inertia ixx="1.27661762368947E-06" ixy="7.27034842413144E-08" ixz="1.62724400979504E-12" iyy="2.31536498425727E-07" iyz="-9.71604458446237E-12" izz="1.23907231734916E-06"/>
    </inertial>
    <visual>
      <origin rpy="0 0 0" xyz="0 0 0"/>
      <geometry>
        <mesh filename="package://ffw_description/meshes/left_hand/left_little_2.STL"/>
      </geometry>
      <material name="">
        <color rgba="0.792156862745098 0.819607843137255 0.933333333333333 1"/>
      </material>
    </visual>
    <collision>
      <origin rpy="0 0 0" xyz="0 0 0"/>
      <geometry>
        <mesh filename="package://ffw_description/meshes/left_hand/left_little_2.STL"/>
      </geometry>
    </collision>
  </link>
  <joint name="left_little_2_joint" type="revolute">
    <origin rpy="0 0 0" xyz="-0.005182 0.032363 -0.00055"/>
    <parent link="left_little_1"/>
    <child link="left_little_2"/>
    <axis xyz="0 0 1"/>
    <limit effort="10" lower="0" upper="3.14" velocity="1"/>
    <mimic joint="left_little_1_joint" multiplier="1.18" offset="0"/>
  </joint>
  <link name="base_link_right_hand">
    <inertial>
      <origin rpy="0 0 0" xyz="-4.91696692515552E-05 -0.00297934158474353 -0.0724838074966582"/>
      <mass value="0.260034351097693"/>
      <inertia ixx="0.000240584294557413" ixy="1.12900341553271E-06" ixz="5.34716263010627E-07" iyy="0.000284423438713157" iyz="-1.41174524262487E-05" izz="0.000155854672271766"/>
    </inertial>
    <visual>
      <origin rpy="0 0 0" xyz="0 0 0"/>
      <geometry>
        <mesh filename="package://ffw_description/meshes/right_hand/base_link.STL"/>
      </geometry>
      <material name="">
        <color rgba="1 1 1 1"/>
      </material>
    </visual>
    <collision>
      <origin rpy="0 0 0" xyz="0 0 0"/>
      <geometry>
        <mesh filename="package://ffw_description/meshes/right_hand/base_link.STL"/>
      </geometry>
    </collision>
  </link>
  <link name="right_thumb_1">
    <inertial>
      <origin rpy="0 0 0" xyz="-0.00178423179132732 0.000649410769092404 0.00488589310434417"/>
      <mass value="0.00115518743162309"/>
      <inertia ixx="5.98911473694571E-08" ixy="-8.04324266712912E-09" ixz="-3.29346964287939E-09" iyy="4.07201940087006E-08" iyz="1.1987242259973E-09" izz="6.18161684388651E-08"/>
    </inertial>
    <visual>
      <origin rpy="0 0 0" xyz="0 0 0"/>
      <geometry>
        <mesh filename="package://ffw_description/meshes/right_hand/right_thumb_1.STL"/>
      </geometry>
      <material name="">
        <color rgba="1 1 1 1"/>
      </material>
    </visual>
    <collision>
      <origin rpy="0 0 0" xyz="0 0 0"/>
      <geometry>
        <mesh filename="package://ffw_description/meshes/right_hand/right_thumb_1.STL"/>
      </geometry>
    </collision>
  </link>
  <joint name="right_thumb_1_joint" type="revolute">
    <origin rpy="-3.1416 0 -3.1416" xyz="0.0269 0.02101 -0.069"/>
    <parent link="base_link_right_hand"/>
    <child link="right_thumb_1"/>
    <axis xyz="0 0 -1"/>
    <limit effort="10" lower="0" upper="1.15" velocity="1"/>
  </joint>
  <link name="right_thumb_2">
    <inertial>
      <origin rpy="0 0 0" xyz="0.0141071308121962 0.0132720367246953 -0.00905029680056009"/>
      <mass value="0.016"/>
      <inertia ixx="1.06573287501608E-06" ixy="-7.61985755293293E-08" ixz="-2.57609628655293E-11" iyy="1.06536320559038E-06" iyz="5.09603163270097E-12" izz="1.39688473195303E-06"/>
    </inertial>
    <visual>
      <origin rpy="0 0 0" xyz="0 0 0"/>
      <geometry>
        <mesh filename="package://ffw_description/meshes/right_hand/right_thumb_2.STL"/>
      </geometry>
      <material name="">
        <color rgba="1 1 1 1"/>
      </material>
    </visual>
    <collision>
      <origin rpy="0 0 0" xyz="0 0 0"/>
      <geometry>
        <mesh filename="package://ffw_description/meshes/right_hand/right_thumb_2.STL"/>
      </geometry>
    </collision>
  </link>
  <joint name="right_thumb_2_joint" type="revolute">
    <origin rpy="1.5708 0 2.7925" xyz="-0.0063016 0.011924 0.003"/>
    <parent link="right_thumb_1"/>
    <child link="right_thumb_2"/>
    <axis xyz="0 0 1"/>
    <limit effort="10" lower="0" upper="0.55" velocity="1"/>
  </joint>
  <link name="right_thumb_3">
    <inertial>
      <origin rpy="0 0 0" xyz="0.00937843602210774 0.00404407714692963 -0.00753947150343212"/>
      <mass value="0.012"/>
      <inertia ixx="4.67837152048068E-07" ixy="-4.50034504480504E-08" ixz="-7.50604972036399E-11" iyy="3.98821847444202E-07" iyz="-2.80308780973008E-10" izz="4.24792779381109E-07"/>
    </inertial>
    <visual>
      <origin rpy="0 0 0" xyz="0 0 0"/>
      <geometry>
        <mesh filename="package://ffw_description/meshes/right_hand/right_thumb_3.STL"/>
      </geometry>
      <material name="">
        <color rgba="1 1 1 1"/>
      </material>
    </visual>
    <collision>
      <origin rpy="0 0 0" xyz="0 0 0"/>
      <geometry>
        <mesh filename="package://ffw_description/meshes/right_hand/right_thumb_3.STL"/>
      </geometry>
    </collision>
  </link>
  <joint name="right_thumb_3_joint" type="revolute">
    <origin rpy="0 0 0" xyz="0.034968 0.021325 -0.0015"/>
    <parent link="right_thumb_2"/>
    <child link="right_thumb_3"/>
    <axis xyz="0 0 1"/>
    <limit effort="10" lower="0" upper="3.14" velocity="1"/>
    <mimic joint="right_thumb_2_joint" multiplier="0.60" offset="0"/>
  </joint>
  <link name="right_thumb_4">
    <inertial>
      <origin rpy="0 0 0" xyz="0.0109973997213043 0.00131062737520288 -0.0073435196000655"/>
      <mass value="0.01"/>
      <inertia ixx="6.43617695804108E-07" ixy="-2.57371067432159E-07" ixz="8.83834214745077E-10" iyy="7.63665185138253E-07" iyz="7.47494238463672E-10" izz="9.2568863295396E-07"/>
    </inertial>
    <visual>
      <origin rpy="0 0 0" xyz="0 0 0"/>
      <geometry>
        <mesh filename="package://ffw_description/meshes/right_hand/right_thumb_4.STL"/>
      </geometry>
      <material name="">
        <color rgba="1 1 1 1"/>
      </material>
    </visual>
    <collision>
      <origin rpy="0 0 0" xyz="0 0 0"/>
      <geometry>
        <mesh filename="package://ffw_description/meshes/right_hand/right_thumb_4.STL"/>
      </geometry>
    </collision>
  </link>
  <joint name="right_thumb_4_joint" type="revolute">
    <origin rpy="0 0 0" xyz="0.018887 0.011501 -0.0002"/>
    <parent link="right_thumb_3"/>
    <child link="right_thumb_4"/>
    <axis xyz="0 0 1"/>
    <limit effort="10" lower="0" upper="3.14" velocity="1"/>
    <mimic joint="right_thumb_2_joint" multiplier="0.8" offset="0"/>
  </joint>
  <link name="right_index_1">
    <inertial>
      <origin rpy="0 0 0" xyz="-0.00183546255523356 0.0123552521861834 -0.00664922294778368"/>
      <mass value="0.00719999389753264"/>
      <inertia ixx="1.28371991025318E-06" ixy="4.21564829206078E-08" ixz="-4.10859703056649E-12" iyy="5.79478432222904E-07" iyz="6.39690407239206E-11" izz="1.32925246769088E-06"/>
    </inertial>
    <visual>
      <origin rpy="0 0 0" xyz="0 0 0"/>
      <geometry>
        <mesh filename="package://ffw_description/meshes/right_hand/right_index_1.STL"/>
      </geometry>
      <material name="">
        <color rgba="1 1 1 1"/>
      </material>
    </visual>
    <collision>
      <origin rpy="0 0 0" xyz="0 0 0"/>
      <geometry>
        <mesh filename="package://ffw_description/meshes/right_hand/right_index_1.STL"/>
      </geometry>
    </collision>
  </link>
  <joint name="right_index_1_joint" type="revolute">
    <origin rpy="-1.5359 0 -1.5708" xyz="0.038679 0.00056467 -0.1564"/>
    <parent link="base_link_right_hand"/>
    <child link="right_index_1"/>
    <axis xyz="0 0 1"/>
    <limit effort="10" lower="0" upper="1.6" velocity="1"/>
  </joint>
  <link name="right_index_2">
    <inertial>
      <origin rpy="0 0 0" xyz="0.000405081354201142 0.0257028143581744 -0.00609275623125877"/>
      <mass value="0.0096859422185797"/>
      <inertia ixx="2.25513837942244E-06" ixy="4.11239564383381E-07" ixz="-3.94499739658711E-10" iyy="3.91290903748666E-07" iyz="2.79706871963245E-09" izz="2.30200483771215E-06"/>
    </inertial>
    <visual>
      <origin rpy="0 0 0" xyz="0 0 0"/>
      <geometry>
        <mesh filename="package://ffw_description/meshes/right_hand/right_index_2.STL"/>
      </geometry>
      <material name="">
        <color rgba="1 1 1 1"/>
      </material>
    </visual>
    <collision>
      <origin rpy="0 0 0" xyz="0 0 0"/>
      <geometry>
        <mesh filename="package://ffw_description/meshes/right_hand/right_index_2.STL"/>
      </geometry>
    </collision>
  </link>
  <joint name="right_index_2_joint" type="revolute">
    <origin rpy="0 0 0" xyz="-0.0016312 0.032734 -0.00055"/>
    <parent link="right_index_1"/>
    <child link="right_index_2"/>
    <axis xyz="0 0 1"/>
    <limit effort="10" lower="0" upper="3.14" velocity="1"/>
    <mimic joint="right_index_1_joint" multiplier="1.05" offset="0"/>
  </joint>
  <link name="right_middle_1">
    <inertial>
      <origin rpy="0 0 0" xyz="-0.00229221489529491 0.0122787164691098 -0.00664923691414206"/>
      <mass value="0.00719999454699651"/>
      <inertia ixx="1.27961146095209E-06" ixy="6.81307502326408E-08" ixz="-6.13869092479439E-12" iyy="5.83570383259162E-07" iyz="6.33401074034573E-11" izz="1.32923656099557E-06"/>
    </inertial>
    <visual>
      <origin rpy="0 0 0" xyz="0 0 0"/>
      <geometry>
        <mesh filename="package://ffw_description/meshes/right_hand/right_middle_1.STL"/>
      </geometry>
      <material name="">
        <color rgba="1 1 1 1"/>
      </material>
    </visual>
    <collision>
      <origin rpy="0 0 0" xyz="0 0 0"/>
      <geometry>
        <mesh filename="package://ffw_description/meshes/right_hand/right_middle_1.STL"/>
      </geometry>
    </collision>
  </link>
  <joint name="right_middle_1_joint" type="revolute">
    <origin rpy="-1.5708 0 -1.5708" xyz="0.0171 0.00056467 -0.157"/>
    <parent link="base_link_right_hand"/>
    <child link="right_middle_1"/>
    <axis xyz="0 0 1"/>
    <limit effort="10" lower="0" upper="1.6" velocity="1"/>
  </joint>
  <link name="right_middle_2">
    <inertial>
      <origin rpy="0 0 0" xyz="7.55635061812504E-05 0.0274472409700489 -0.00610051225570537"/>
      <mass value="0.0104603374357648"/>
      <inertia ixx="2.75802690517233E-06" ixy="4.66354191789105E-07" ixz="-3.73412436067728E-12" iyy="4.22418749660047E-07" iyz="7.48571284682703E-11" izz="2.80694637912416E-06"/>
    </inertial>
    <visual>
      <origin rpy="0 0 0" xyz="0 0 0"/>
      <geometry>
        <mesh filename="package://ffw_description/meshes/right_hand/right_middle_2.STL"/>
      </geometry>
      <material name="">
        <color rgba="1 1 1 1"/>
      </material>
    </visual>
    <collision>
      <origin rpy="0 0 0" xyz="0 0 0"/>
      <geometry>
        <mesh filename="package://ffw_description/meshes/right_hand/right_middle_2.STL"/>
      </geometry>
    </collision>
  </link>
  <joint name="right_middle_2_joint" type="revolute">
    <origin rpy="0 0 0" xyz="-0.0028436 0.032651 -0.00055"/>
    <parent link="right_middle_1"/>
    <child link="right_middle_2"/>
    <axis xyz="0 0 1"/>
    <limit effort="10" lower="0" upper="3.14" velocity="1"/>
    <mimic joint="right_middle_1_joint" multiplier="1.05" offset="0"/>
  </joint>
  <link name="right_ring_1">
    <inertial>
      <origin rpy="0 0 0" xyz="-0.00240481178777661 0.0122571709475593 -0.00664923625225445"/>
      <mass value="0.00719998997814135"/>
      <inertia ixx="1.27830103769765E-06" ixy="7.45073064952646E-08" ixz="-6.73880804360017E-12" iyy="5.84879553082369E-07" iyz="6.3350585052199E-11" izz="1.32923557625193E-06"/>
    </inertial>
    <visual>
      <origin rpy="0 0 0" xyz="0 0 0"/>
      <geometry>
        <mesh filename="package://ffw_description/meshes/right_hand/right_ring_1.STL"/>
      </geometry>
      <material name="">
        <color rgba="1 1 1 1"/>
      </material>
    </visual>
    <collision>
      <origin rpy="0 0 0" xyz="0 0 0"/>
      <geometry>
        <mesh filename="package://ffw_description/meshes/right_hand/right_ring_1.STL"/>
      </geometry>
    </collision>
  </link>
  <joint name="right_ring_1_joint" type="revolute">
    <origin rpy="-1.6232 0 -1.5708" xyz="-0.0045302 0.00056467 -0.15683"/>
    <parent link="base_link_right_hand"/>
    <child link="right_ring_1"/>
    <axis xyz="0 0 1"/>
    <limit effort="10" lower="0" upper="1.6" velocity="1"/>
  </joint>
  <link name="right_ring_2">
    <inertial>
      <origin rpy="0 0 0" xyz="0.000666830906754845 0.0256973412492289 -0.0060927714564012"/>
      <mass value="0.0096859390369724"/>
      <inertia ixx="2.26332196405867E-06" ixy="3.92172318180451E-07" ixz="-3.65715440420713E-10" iyy="3.83108005467821E-07" iyz="2.80158649618184E-09" izz="2.30200501593561E-06"/>
    </inertial>
    <visual>
      <origin rpy="0 0 0" xyz="0 0 0"/>
      <geometry>
        <mesh filename="package://ffw_description/meshes/right_hand/right_ring_2.STL"/>
      </geometry>
      <material name="">
        <color rgba="1 1 1 1"/>
      </material>
    </visual>
    <collision>
      <origin rpy="0 0 0" xyz="0 0 0"/>
      <geometry>
        <mesh filename="package://ffw_description/meshes/right_hand/right_ring_2.STL"/>
      </geometry>
    </collision>
  </link>
  <joint name="right_ring_2_joint" type="revolute">
    <origin rpy="0 0 0" xyz="-0.0031431 0.032624 -0.00055"/>
    <parent link="right_ring_1"/>
    <child link="right_ring_2"/>
    <axis xyz="0 0 1"/>
    <limit effort="10" lower="0" upper="3.14" velocity="1"/>
    <mimic joint="right_ring_1_joint" multiplier="1.05" offset="0"/>
  </joint>
  <link name="right_little_1">
    <inertial>
      <origin rpy="0 0 0" xyz="-0.00316844591541324 0.0120823779446085 -0.00664923024026526"/>
      <mass value="0.00719994987013217"/>
      <inertia ixx="1.26624415714453E-06" ixy="1.17303714016617E-07" ixz="-1.15327375313821E-11" iyy="5.96925804604496E-07" iyz="6.36110319315301E-11" izz="1.32922857962206E-06"/>
    </inertial>
    <visual>
      <origin rpy="0 0 0" xyz="0 0 0"/>
      <geometry>
        <mesh filename="package://ffw_description/meshes/right_hand/right_little_1.STL"/>
      </geometry>
      <material name="">
        <color rgba="1 1 1 1"/>
      </material>
    </visual>
    <collision>
      <origin rpy="0 0 0" xyz="0 0 0"/>
      <geometry>
        <mesh filename="package://ffw_description/meshes/right_hand/right_little_1.STL"/>
      </geometry>
    </collision>
  </link>
  <joint name="right_little_1_joint" type="revolute">
    <origin rpy="-1.6755 0 -1.5708" xyz="-0.025916 0.00056467 -0.15365"/>
    <parent link="base_link_right_hand"/>
    <child link="right_little_1"/>
    <axis xyz="0 0 1"/>
    <limit effort="10" lower="0" upper="1.6" velocity="1"/>
  </joint>
  <link name="right_little_2">
    <inertial>
      <origin rpy="0 0 0" xyz="0.0204417303421136 -0.00469494170410353 -0.00609999668427265"/>
      <mass value="0.0075928240732547"/>
      <inertia ixx="2.31546812157118E-07" ixy="-7.27021381773956E-08" ixz="2.3664966486269E-11" iyy="1.27663957628266E-06" iyz="-7.58283070676144E-12" izz="1.23909562166535E-06"/>
    </inertial>
    <visual>
      <origin rpy="0 0 0" xyz="0 0 0"/>
      <geometry>
        <mesh filename="package://ffw_description/meshes/right_hand/right_little_2.STL"/>
      </geometry>
      <material name="">
        <color rgba="1 1 1 1"/>
      </material>
    </visual>
    <collision>
      <origin rpy="0 0 0" xyz="0 0 0"/>
      <geometry>
        <mesh filename="package://ffw_description/meshes/right_hand/right_little_2.STL"/>
      </geometry>
    </collision>
  </link>
  <joint name="right_little_2_joint" type="revolute">
    <origin rpy="0 0 1.5708" xyz="-0.005182 0.032363 -0.00055"/>
    <parent link="right_little_1"/>
    <child link="right_little_2"/>
    <axis xyz="0 0 1"/>
    <limit effort="10" lower="0" upper="3.14" velocity="1"/>
    <mimic joint="right_little_1_joint" multiplier="1.18" offset="0"/>
  </joint>
  <!-- World -->
  <link name="world"/>
  <joint name="world_fixed" type="fixed">
    <parent link="world"/>
    <child link="base_link"/>
    <origin rpy="0 0 0" xyz="0.0 0.0 0.0"/>
  </joint>
  <joint name="left_hand_fixed" type="fixed">
    <origin rpy="0 0 0" xyz="0 0 -0.05"/>
    <parent link="arm_l_link7"/>
    <axis xyz="0 0 0"/>
    <child link="base_link_left_hand"/>
  </joint>
  <joint name="right_hand_fixed" type="fixed">
    <origin rpy="0 0 0" xyz="0 0 -0.05"/>
    <parent link="arm_r_link7"/>
    <axis xyz="0 0 0"/>
    <child link="base_link_right_hand"/>
  </joint>
</robot>
